Workbook

Sheet Portada

Sheet Venta total
B2: VENTA GENERAL
W3: Año | X3: Acumulado
W4: 2021 | X4: ='Tablas vta Tot'!$K4 -> 4.9470344e+08 | Y4: =SIGN(X5-X4) -> -1
W5: 2022 | X5: ='Tablas vta Tot'!$K5 -> 3.5985424e+08 | Y5: -67863040
W7: 2021 vs 2022
W8: ='Tablas vta Tot'!C3 -> Enero | X8: ='Tablas vta Tot'!C7 -> 0.060764215 | Y8: =SIGN(X8) -> 1
W9: ='Tablas vta Tot'!D3 -> Febrero | X9: ='Tablas vta Tot'!D7 -> -0.22404753 | Y9: =SIGN(X9) -> -1
W10: ='Tablas vta Tot'!E3 -> Marzo | X10: ='Tablas vta Tot'!E7 -> -0.044883413 | Y10: =SIGN(X10) -> -1
W11: ='Tablas vta Tot'!F3 -> Abril | X11: ='Tablas vta Tot'!F7 -> -0.24110197 | Y11: =SIGN(X11) -> -1
W12: ='Tablas vta Tot'!G3 -> Mayo | X12: ='Tablas vta Tot'!G7 -> -0.26930816 | Y12: =SIGN(X12) -> -1
W13: ='Tablas vta Tot'!H3 -> Junio | X13: ='Tablas vta Tot'!H7 -> -0.06511102 | Y13: =SIGN(X13) -> -1
W14: ='Tablas vta Tot'!I3 -> Julio | X14: ='Tablas vta Tot'!I7 -> -0.19103641 | Y14: =SIGN(X14) -> -1
W15: ='Tablas vta Tot'!J3 -> Agosto | X15: ='Tablas vta Tot'!J7 -> -0.45855055 | Y15: =SIGN(X15) -> -1
W17: =W14&" vs "&W15 -> Julio vs Agosto
W18: ='Tablas vta Tot'!L7 -> -0.14016513 | Y18: =SIGN(X19-X18) -> 0
Y19: -67863040
B21: VENTA CLIENTE 1
W22: Año | X22: =X3 -> Acumulado
W23: 2021 | X23: ='Tablas vta Tot'!K11 -> 142228409 | Y23: =SIGN(X24-X23) -> 1
W24: 2022 | X24: ='Tablas vta Tot'!K12 -> 1.5660559e+08 | Y24: -67863040
W26: 2021 vs 2022
W27: ='Tablas vta Tot'!C10 -> Enero | X27: ='Tablas vta Tot'!C14 -> -0.0049064708 | Y27: =SIGN(X27) -> -1
W28: ='Tablas vta Tot'!D10 -> Febrero | X28: ='Tablas vta Tot'!D14 -> -0.003920158 | Y28: =SIGN(X28) -> -1
W29: ='Tablas vta Tot'!E10 -> Marzo | X29: ='Tablas vta Tot'!E14 -> 0.11071742 | Y29: =SIGN(X29) -> 1
W30: ='Tablas vta Tot'!F10 -> Abril | X30: ='Tablas vta Tot'!F14 -> 0.13494724 | Y30: =SIGN(X30) -> 1
W31: ='Tablas vta Tot'!G10 -> Mayo | X31: ='Tablas vta Tot'!G14 -> 0.00067447603 | Y31: =SIGN(X31) -> 1
W32: ='Tablas vta Tot'!H10 -> Junio | X32: ='Tablas vta Tot'!H14 -> 0.11868765 | Y32: =SIGN(X32) -> 1
W33: ='Tablas vta Tot'!I10 -> Julio | X33: ='Tablas vta Tot'!I14 -> 0.038483159 | Y33: =SIGN(X33) -> 1
W34: ='Tablas vta Tot'!J10 -> Agosto | X34: ='Tablas vta Tot'!J14 -> -0.034568293 | Y34: =SIGN(X34) -> -1
W36: =$W$17 -> Julio vs Agosto
W37: ='Tablas vta Tot'!L21 -> -0.62058548 | Y37: =SIGN(X38-X37) -> 0
Y38: -67863040
B40: VENTA CLIENTE 2
W41: Año | X41: =X3 -> Acumulado
W42: 2021 | X42: ='Tablas vta Tot'!K18 -> 2.9237371e+08 | Y42: =SIGN(X43-X42) -> -1
W43: 2022 | X43: ='Tablas vta Tot'!K19 -> 1.5411632e+08 | Y43: -67863040
W45: 2021 vs 2022
W46: ='Tablas vta Tot'!C17 -> Enero | X46: ='Tablas vta Tot'!C21 -> 0.080440767 | Y46: =SIGN(X46) -> 1
W47: ='Tablas vta Tot'!D17 -> Febrero | X47: ='Tablas vta Tot'!D21 -> -0.24136223 | Y47: =SIGN(X47) -> -1
W48: ='Tablas vta Tot'!E17 -> Marzo | X48: ='Tablas vta Tot'!E21 -> -0.3181621 | Y48: =SIGN(X48) -> -1
...

Sheet Tablas vta Tot
B2: Venta General
B3: Año | C3: Enero | D3: Febrero | E3: Marzo | F3: Abril | G3: Mayo | H3: Junio | I3: Julio | J3: Agosto | K3: Suma | L3: Mes aterior vs actual
B4: 2021 | C4: 83865948 | D4: 78063587 | E4: 53222539 | F4: 58269002 | G4: 40625605 | H4: 46512449 | I4: 56367991 | J4: 77776316 | K4: =SUM('Tablas vta Tot'!$C4:$J4) -> 4.9470344e+08 | L4: Diferencia
B5: 2022 | C5: 94717427 | D5: 49486341 | E5: 48650146 | F5: 35629813 | G5: 23386596 | H5: 40825769 | I5: 38285692 | J5: =J12+J19+J27 -> 28872461 | K5: =SUM('Tablas vta Tot'!$C5:$J5) -> 3.5985424e+08 | L5: =J5-I5 -> -9413231
B6: Diferencia | C6: =C5-C4 -> 10851479 | D6: =D5-D4 -> -28577246 | E6: =E5-E4 -> -4572393.8 | F6: =F5-F4 -> -22639189 | G6: =G5-G4 -> -17239008 | H6: =H5-H4 -> -5686680.4 | I6: =I5-I4 -> -18082300 | J6: =J5-J4 -> -48903855 | K6: =SUM('Tablas vta Tot'!$C6:$J6) -> -1.3484919e+08 | L6: Porcentaje
B7: Porcentaje | C7: =IFERROR(C6/SUM(C4:C5),"-") -> 0.060764215 | D7: =IFERROR(D6/SUM(D4:D5),"-") -> -0.22404753 | E7: =IFERROR(E6/SUM(E4:E5),"-") -> -0.044883413 | F7: =IFERROR(F6/SUM(F4:F5),"-") -> -0.24110197 | G7: =IFERROR(G6/SUM(G4:G5),"-") -> -0.26930816 | H7: =IFERROR(H6/SUM(H4:H5),"-") -> -0.06511102 | I7: =IFERROR(I6/SUM(I4:I5),"-") -> -0.19103641 | J7: =IFERROR(J6/SUM(J4:J5),"-") -> -0.45855055 | K7: =K6/SUM(K4:K5) -> -0.15779999 | L7: =L5/SUM(I5:J5) -> -0.14016513
B9: Venta Cliente 1
B10: Año | C10: Enero | D10: Febrero | E10: Marzo | F10: Abril | G10: Mayo | H10: Junio | I10: Julio | J10: Agosto | K10: Suma | L10: Mes aterior vs actual
B11: 2021 | C11: 14313449 | D11: 19156433 | E11: 16565163 | F11: 17274313 | G11: 18364061 | H11: 18193314 | I11: 19001221 | J11: 19360455 | K11: =SUM('Tablas vta Tot'!$C11:$J11) -> 142228409 | L11: Diferencia
B12: 2022 | C12: 14173678 | D12: 19006827 | E12: 20689954 | F12: 22663859 | G12: 18388850 | H12: 23093556 | I12: 20522207 | J12: 18066663 | K12: =SUM('Tablas vta Tot'!$C12:$J12) -> 1.5660559e+08 | L12: =J12-I12 -> -2455544
B13: Diferencia | C13: =C12-C11 -> -139771.26 | D13: =D12-D11 -> -149606.01 | E13: =E12-E11 -> 4124790.5 | F13: =F12-F11 -> 5389545.9 | G13: =G12-G11 -> 24788.958 | H13: =H12-H11 -> 4900241.7 | I13: =I12-I11 -> 1520986.4 | J13: =J12-J11 -> -1293791.6 | K13: =SUM('Tablas vta Tot'!$C13:$J13) -> 14377185 | L13: Porcentaje
B14: Porcentaje | C14: =IFERROR(C13/SUM(C11:C12),"-") -> -0.0049064708 | D14: =IFERROR(D13/SUM(D11:D12),"-") -> -0.003920158 | E14: =IFERROR(E13/SUM(E11:E12),"-") -> 0.11071742 | F14: =IFERROR(F13/SUM(F11:F12),"-") -> 0.13494724 | G14: =IFERROR(G13/SUM(G11:G12),"-") -> 0.00067447603 | H14: =IFERROR(H13/SUM(H11:H12),"-") -> 0.11868765 | I14: =IFERROR(I13/SUM(I11:I12),"-") -> 0.038483159 | J14: =IFERROR(J13/SUM(J11:J12),"-") -> -0.034568293 | K14: =K13/SUM(K11:K12) -> 0.048110939 | L14: =L12/SUM(I12:J12) -> -0.063633476
B16: Venta Cliente 2
B17: Año | C17: Enero | D17: Febrero | E17: Marzo | F17: Abril | G17: Mayo | H17: Junio | I17: Julio | J17: Agosto | K17: Suma | L17: Mes aterior vs actual
B18: 2021 | C18: 61197973 | D18: 49893245 | E18: 30239827 | F18: 29386565 | G18: 22261544 | H18: 17337678 | I18: =I4-I11-I26 -> 30952821 | J18: 51104058 | K18: =SUM('Tablas vta Tot'!$C18:$J18) -> 2.9237371e+08 | L18: Diferencia
B19: 2022 | C19: 71904867 | D19: 30491422 | E19: 15641976 | F19: 6757580 | G19: 4997746.3 | H19: 9324736.6 | I19: =I5-I12-I27 -> 12152764 | J19: 2845228 | K19: =SUM('Tablas vta Tot'!$C19:$J19) -> 1.5411632e+08 | L19: =J19-I19 -> -9307536.4
B20: Diferencia | C20: =C19-C18 -> 10706895 | D20: =D19-D18 -> -19401823 | E20: =E19-E18 -> -14597851 | F20: =F19-F18 -> -22628985 | G20: =G19-G18 -> -17263797 | H20: =H19-H18 -> -8012941.4 | I20: =I19-I18 -> -18800057 | J20: =J19-J18 -> -48258830 | K20: =SUM('Tablas vta Tot'!$C20:$J20) -> -1.3825739e+08 | L20: Porcentaje
B21: Porcentaje | C21: =IFERROR(C20/SUM(C18:C19),"-") -> 0.080440767 | D21: =IFERROR(D20/SUM(D18:D19),"-") -> -0.24136223 | E21: =IFERROR(E20/SUM(E18:E19),"-") -> -0.3181621 | F21: =IFERROR(F20/SUM(F18:F19),"-") -> -0.62607609 | G21: =IFERROR(G20/SUM(G18:G19),"-") -> -0.63331794 | H21: =IFERROR(H20/SUM(H18:H19),"-") -> -0.30053322 | I21: =IFERROR(I20/SUM(I18:I19),"-") -> -0.43613969 | J21: =IFERROR(J20/SUM(J18:J19),"-") -> -0.89452213 | K21: =K20/SUM(K18:K19) -> -0.30965392 | L21: =L19/SUM(I19:J19) -> -0.62058548
B24: Venta Cliente 3
B25: Año | C25: Enero | D25: Febrero | E25: Marzo | F25: Abril | G25: Mayo | H25: Junio | I25: Julio | J25: Agosto | K25: Suma | L25: Mes aterior vs actual
B26: 2021 | C26: 8354526.4 | D26: 9013908.5 | E26: 6417549.6 | F26: 11608124 | G26: 153875.25 | H26: 10981457 | I26: 6413949 | J26: 7311803 | K26: =SUM('Tablas vta Tot'!$C26:$J26) -> 60255193 | L26: Diferencia
B27: 2022 | C27: 8638881.7 | D27: 0 | E27: 12318216 | F27: 6208374 | G27: 0 | H27: 8407476.7 | I27: 5610719.8 | J27: 7960569.2 | K27: =SUM('Tablas vta Tot'!$C27:$J27) -> 49144237 | L27: =J27-I27 -> 2349849.4
B28: Diferencia | C28: =C27-C26 -> 284355.24 | D28: =D27-D26 -> -9013908.5 | E28: =E27-E26 -> 5900666.6 | F28: =F27-F26 -> -5399749.9 | G28: =G27-G26 -> -153875.25 | H28: =H27-H26 -> -2573980.7 | I28: =I27-I26 -> -803229.12 | J28: =J27-J26 -> 648766.24 | K28: =SUM('Tablas vta Tot'!$C28:$J28) -> -11110955 | L28: Porcentaje
B29: Porcentaje | C29: =IFERROR(C28/SUM(C26:C27),"-") -> 0.016733267 | D29: =IFERROR(D28/SUM(D26:D27),"-") -> -1 | E29: =IFERROR(E28/SUM(E26:E27),"-") -> 0.31494131 | F29: =IFERROR(F28/SUM(F26:F27),"-") -> -0.30307583 | G29: =IFERROR(G28/SUM(G26:G27),"-") -> -1 | H29: =IFERROR(H28/SUM(H26:H27),"-") -> -0.13275514 | I29: =IFERROR(I28/SUM(I26:I27),"-") -> -0.06679844 | J29: =IFERROR(J28/SUM(J26:J27),"-") -> 0.04247973 | K29: =IFERROR(K28/SUM(K26:K27),"-") -> -0.10156319 | L29: =L27/SUM(I27:J27) -> 0.17314858
B33: Estatus | C33: Activo | D33: Inactivo | E33: Total | F33: Sin facturar
B34: Socios | C34: 2111 | D34: 2570 | E34: 5437 | F34: 756
